Workbook

Sheet Program
A1: Remote Pitching Program
A4: Athlete name | B4: Athlete Name
A5: Coach | B5: Coach Name
A6: Start date (Monday) | B6: 46321 | C6: <- every date on the Throwing tab is built from this
A7: Program phase | B7: Off-Season Build
A8: Athlete email / phone
A9: Check-in day | B9: Sunday
A12: Color key
A13: Blue text | B13: Coach fills in (the plan)
A14: Green cells | B14: Athlete fills in (what they actually did)
A15: Black text | B15: Calculates automatically - don't type here
A17: How it works
A18: 1. Coach: fill in the yellow cells above, then write the plan on each tab in blue.
A19: 2. Warm Up tab: the routine the athlete does before every throwing day, with video links.
A20: 3. Throwing tab: one row per day for 8 weeks. Pick a day type, write the throwing plan, set throw counts.
A21: 4. Lifting tab: 3 lift days per week. Athlete logs weight x reps in the green week columns.
A22: 5. Share the file with the athlete (Google Sheets / OneDrive). They fill in the green cells after each session.
A23: 6. On check-in day, review the Weekly Summary on the Throwing tab (throws, arm feel, velo, days completed).
A24: 7. Example entries in week 1 and on the Warm Up / Lifting tabs are samples - edit or replace them.

Sheet Warm Up
A1: Warm Up Routine
A2: ="Athlete: "&Program!$B$4&" Coach: "&Program!$B$5
A3: Do this full routine before every throwing day. Coach: add a video link for each exercise so the athlete can check form.
A5: # | B5: Exercise | C5: Sets | D5: Reps / Time | E5: Coaching Cues | F5: Video Link
A6: DYNAMIC WARM UP
A7: 1 | B7: Jog / Skip | C7: 1 | D7: 2 min | E7: Easy pace, get the blood moving
A8: 2 | B8: World's Greatest Stretch | C8: 1 | D8: 5 / side | E8: Elbow to instep, rotate open to the sky
A9: 3 | B9: Lateral Lunge | C9: 1 | D9: 8 / side | E9: Sit back into the hip, chest up
A10: 4 | B10: Walking Knee Hug + Quad Pull | C10: 1 | D10: 8 / side | E10: Stand tall, squeeze glute
A11: 5 | B11: Carioca | C11: 2 | D11: 20 yds | E11: Quick hips, stay on the balls of the feet
A14: ARM CARE / BANDS
A15: 6 | B15: J-Band Forward Fly | C15: 1 | D15: 10 | E15: Thumbs up, slow and controlled
A16: 7 | B16: J-Band Reverse Fly | C16: 1 | D16: 10 | E16: Squeeze shoulder blades
A17: 8 | B17: J-Band Internal / External Rotation | C17: 1 | D17: 10 / each | E17: Elbow at 90, pinned to the side
A18: 9 | B18: J-Band Throwing Motion | C18: 1 | D18: 10 | E18: Full arm path, finish over the front knee
A19: 10 | B19: Scap Push-Ups | C19: 1 | D19: 10 | E19: Arms locked, move only the shoulder blades
A22: PLYO BALLS / WALL
A23: 11 | B23: Reverse Throws (2 lb) | C23: 1 | D23: 10 | E23: Throw backward over the shoulder, decelerate
A24: 12 | B24: Pivot Pickoffs (1 lb) | C24: 1 | D24: 10 | E24: Load the back hip, rotate through
A25: 13 | B25: Roll-In Throws (1 lb) | C25: 1 | D25: 10 | E25: Rhythm into the throw, intent ~70%

Sheet Throwing
A1: Throwing Program
A2: ="Athlete: "&Program!$B$4&" Coach: "&Program!$B$5
A3: One row per day. Coach fills in blue columns B-H; athlete fills in the green columns after each session.
O4: Weekly Summary
A5: Week | B5: Date | C5: Day | D5: Day Type | E5: Throwing Plan (drills / distances / pitch mix) | F5: Planned Throws | G5: Max Distance (ft) | H5: Intent % | I5: Completed? (Y/N) | J5: Warm Up Done? (Y/N) | K5: Arm Feel (1-10) | L5: Top Velo (mph) | M5: Athlete Notes | O5: Week | P5: Planned Throws | Q5: Days Completed | R5: Avg Arm Feel | S5: Top Velo (mph)
A6: 1 | B6: =IF(Program!$B$6="","",Program!$B$6+0) | C6: =IF(B6="","",TEXT(B6,"ddd")) | D6: Hybrid | E6: Warm up + flat ground 60ft, long toss build to 150ft | F6: 50 | G6: 150 | H6: 70% | O6: 1 | P6: =SUMIFS($F$6:$F$61,$A$6:$A$61,O6) | Q6: =COUNTIFS($A$6:$A$61,O6,$I$6:$I$61,"Y") | R6: =IFERROR(AVERAGEIFS($K$6:$K$61,$A$6:$A$61,O6),"") | S6: =IF(COUNTIFS($A$6:$A$61,O6,$L$6:$L$61,">0")=0,"",_xlfn.MAXIFS($L$6:$L$61,$A$6:$A$61,O6))
A7: 1 | B7: =IF(Program!$B$6="","",Program!$B$6+1) | C7: =IF(B7="","",TEXT(B7,"ddd")) | D7: Recovery | E7: Wall drills + light catch 90ft | F7: 30 | G7: 90 | H7: 50% | O7: 2 | P7: =SUMIFS($F$6:$F$61,$A$6:$A$61,O7) | Q7: =COUNTIFS($A$6:$A$61,O7,$I$6:$I$61,"Y") | R7: =IFERROR(AVERAGEIFS($K$6:$K$61,$A$6:$A$61,O7),"") | S7: =IF(COUNTIFS($A$6:$A$61,O7,$L$6:$L$61,">0")=0,"",_xlfn.MAXIFS($L$6:$L$61,$A$6:$A$61,O7))
A8: 1 | B8: =IF(Program!$B$6="","",Program!$B$6+2) | C8: =IF(B8="","",TEXT(B8,"ddd")) | D8: High Intent | E8: Pull-downs, plyo velo throws | F8: 40 | G8: 180 | H8: 90% | O8: 3 | P8: =SUMIFS($F$6:$F$61,$A$6:$A$61,O8) | Q8: =COUNTIFS($A$6:$A$61,O8,$I$6:$I$61,"Y") | R8: =IFERROR(AVERAGEIFS($K$6:$K$61,$A$6:$A$61,O8),"") | S8: =IF(COUNTIFS($A$6:$A$61,O8,$L$6:$L$61,">0")=0,"",_xlfn.MAXIFS($L$6:$L$61,$A$6:$A$61,O8))
A9: 1 | B9: =IF(Program!$B$6="","",Program!$B$6+3) | C9: =IF(B9="","",TEXT(B9,"ddd")) | D9: Off | E9: Arm care only | O9: 4 | P9: =SUMIFS($F$6:$F$61,$A$6:$A$61,O9) | Q9: =COUNTIFS($A$6:$A$61,O9,$I$6:$I$61,"Y") | R9: =IFERROR(AVERAGEIFS($K$6:$K$61,$A$6:$A$61,O9),"") | S9: =IF(COUNTIFS($A$6:$A$61,O9,$L$6:$L$61,">0")=0,"",_xlfn.MAXIFS($L$6:$L$61,$A$6:$A$61,O9))
A10: 1 | B10: =IF(Program!$B$6="","",Program!$B$6+4) | C10: =IF(B10="","",TEXT(B10,"ddd")) | D10: Bullpen | E10: 25 pitches: 15 FB, 5 CH, 5 CB - command focus | F10: 25 | G10: 60 | H10: 80% | O10: 5 | P10: =SUMIFS($F$6:$F$61,$A$6:$A$61,O10) | Q10: =COUNTIFS($A$6:$A$61,O10,$I$6:$I$61,"Y") | R10: =IFERROR(AVERAGEIFS($K$6:$K$61,$A$6:$A$61,O10),"") | S10: =IF(COUNTIFS($A$6:$A$61,O10,$L$6:$L$61,">0")=0,"",_xlfn.MAXIFS($L$6:$L$61,$A$6:$A$61,O10))
A11: 1 | B11: =IF(Program!$B$6="","",Program!$B$6+5) | C11: =IF(B11="","",TEXT(B11,"ddd")) | D11: Recovery | E11: Light catch 90ft | F11: 30 | G11: 90 | H11: 50% | O11: 6 | P11: =SUMIFS($F$6:$F$61,$A$6:$A$61,O11) | Q11: =COUNTIFS($A$6:$A$61,O11,$I$6:$I$61,"Y") | R11: =IFERROR(AVERAGEIFS($K$6:$K$61,$A$6:$A$61,O11),"") | S11: =IF(COUNTIFS($A$6:$A$61,O11,$L$6:$L$61,">0")=0,"",_xlfn.MAXIFS($L$6:$L$61,$A$6:$A$61,O11))
A12: 1 | B12: =IF(Program!$B$6="","",Program!$B$6+6) | C12: =IF(B12="","",TEXT(B12,"ddd")) | D12: Off | E12: Full rest - check-in with coach | O12: 7 | P12: =SUMIFS($F$6:$F$61,$A$6:$A$61,O12) | Q12: =COUNTIFS($A$6:$A$61,O12,$I$6:$I$61,"Y") | R12: =IFERROR(AVERAGEIFS($K$6:$K$61,$A$6:$A$61,O12),"") | S12: =IF(COUNTIFS($A$6:$A$61,O12,$L$6:$L$61,">0")=0,"",_xlfn.MAXIFS($L$6:$L$61,$A$6:$A$61,O12))
A13: 2 | B13: =IF(Program!$B$6="","",Program!$B$6+7) | C13: =IF(B13="","",TEXT(B13,"ddd")) | O13: 8 | P13: =SUMIFS($F$6:$F$61,$A$6:$A$61,O13) | Q13: =COUNTIFS($A$6:$A$61,O13,$I$6:$I$61,"Y") | R13: =IFERROR(AVERAGEIFS($K$6:$K$61,$A$6:$A$61,O13),"") | S13: =IF(COUNTIFS($A$6:$A$61,O13,$L$6:$L$61,">0")=0,"",_xlfn.MAXIFS($L$6:$L$61,$A$6:$A$61,O13))
A14: 2 | B14: =IF(Program!$B$6="","",Program!$B$6+8) | C14: =IF(B14="","",TEXT(B14,"ddd"))
A15: 2 | B15: =IF(Program!$B$6="","",Program!$B$6+9) | C15: =IF(B15="","",TEXT(B15,"ddd")) | O15: Arm feel of 5 or lower turns red - follow up with the athlete.
A16: 2 | B16: =IF(Program!$B$6="","",Program!$B$6+10) | C16: =IF(B16="","",TEXT(B16,"ddd"))
A17: 2 | B17: =IF(Program!$B$6="","",Program!$B$6+11) | C17: =IF(B17="","",TEXT(B17,"ddd"))
A18: 2 | B18: =IF(Program!$B$6="","",Program!$B$6+12) | C18: =IF(B18="","",TEXT(B18,"ddd"))
A19: 2 | B19: =IF(Program!$B$6="","",Program!$B$6+13) | C19: =IF(B19="","",TEXT(B19,"ddd"))
A20: 3 | B20: =IF(Program!$B$6="","",Program!$B$6+14) | C20: =IF(B20="","",TEXT(B20,"ddd"))
A21: 3 | B21: =IF(Program!$B$6="","",Program!$B$6+15) | C21: =IF(B21="","",TEXT(B21,"ddd"))
A22: 3 | B22: =IF(Program!$B$6="","",Program!$B$6+16) | C22: =IF(B22="","",TEXT(B22,"ddd"))
A23: 3 | B23: =IF(Program!$B$6="","",Program!$B$6+17) | C23: =IF(B23="","",TEXT(B23,"ddd"))
A24: 3 | B24: =IF(Program!$B$6="","",Program!$B$6+18) | C24: =IF(B24="","",TEXT(B24,"ddd"))
A25: 3 | B25: =IF(Program!$B$6="","",Program!$B$6+19) | C25: =IF(B25="","",TEXT(B25,"ddd"))
A26: 3 | B26: =IF(Program!$B$6="","",Program!$B$6+20) | C26: =IF(B26="","",TEXT(B26,"ddd"))
A27: 4 | B27: =IF(Program!$B$6="","",Program!$B$6+21) | C27: =IF(B27="","",TEXT(B27,"ddd"))
A28: 4 | B28: =IF(Program!$B$6="","",Program!$B$6+22) | C28: =IF(B28="","",TEXT(B28,"ddd"))
A29: 4 | B29: =IF(Program!$B$6="","",Program!$B$6+23) | C29: =IF(B29="","",TEXT(B29,"ddd"))
A30: 4 | B30: =IF(Program!$B$6="","",Program!$B$6+24) | C30: =IF(B30="","",TEXT(B30,"ddd"))
A31: 4 | B31: =IF(Program!$B$6="","",Program!$B$6+25) | C31: =IF(B31="","",TEXT(B31,"ddd"))
A32: 4 | B32: =IF(Program!$B$6="","",Program!$B$6+26) | C32: =IF(B32="","",TEXT(B32,"ddd"))
A33: 4 | B33: =IF(Program!$B$6="","",Program!$B$6+27) | C33: =IF(B33="","",TEXT(B33,"ddd"))
A34: 5 | B34: =IF(Program!$B$6="","",Program!$B$6+28) | C34: =IF(B34="","",TEXT(B34,"ddd"))
A35: 5 | B35: =IF(Program!$B$6="","",Program!$B$6+29) | C35: =IF(B35="","",TEXT(B35,"ddd"))
A36: 5 | B36: =IF(Program!$B$6="","",Program!$B$6+30) | C36: =IF(B36="","",TEXT(B36,"ddd"))
A37: 5 | B37: =IF(Program!$B$6="","",Program!$B$6+31) | C37: =IF(B37="","",TEXT(B37,"ddd"))
A38: 5 | B38: =IF(Program!$B$6="","",Program!$B$6+32) | C38: =IF(B38="","",TEXT(B38,"ddd"))
A39: 5 | B39: =IF(Program!$B$6="","",Program!$B$6+33) | C39: =IF(B39="","",TEXT(B39,"ddd"))
A40: 5 | B40: =IF(Program!$B$6="","",Program!$B$6+34) | C40: =IF(B40="","",TEXT(B40,"ddd"))
...

Sheet Lifting
A1: Lifting Program
A2: ="Athlete: "&Program!$B$4&" Coach: "&Program!$B$5
A3: 3 lift days per week. Coach fills in blue columns; athlete logs weight x reps (e.g. 135x8) in the green week columns.
A5: # | B5: Exercise | C5: Sets | D5: Reps | E5: Rest / Tempo | F5: Coaching Cues | G5: Video Link | H5: Week 1 | I5: Week 2 | J5: Week 3 | K5: Week 4 | L5: Week 5 | M5: Week 6 | N5: Week 7 | O5: Week 8 | P5: Athlete Notes
A6: DAY 1 - LOWER BODY (Monday)
A7: 1 | B7: Trap Bar Deadlift | C7: 4 | D7: 5 | E7: 2 min | F7: Hips back, push the floor away | H7: 225x5
A8: 2 | B8: Rear Foot Elevated Split Squat | C8: 3 | D8: 8 / leg | E8: 90 sec | F8: Front shin vertical, control down
A9: 3 | B9: Lateral Box Step-Up | C9: 3 | D9: 8 / leg | E9: 60 sec | F9: Drive through the full foot
A10: 4 | B10: Single-Leg RDL | C10: 3 | D10: 8 / leg | E10: 60 sec | F10: Hinge, square hips, soft knee
A11: 5 | B11: Copenhagen Plank | C11: 3 | D11: 20 sec / side | E11: 45 sec | F11: Straight line, ribs down
A12: 6 | B12: Med Ball Rotational Scoop Toss | C12: 3 | D12: 5 / side | E12: 60 sec | F12: Load back hip, explode through
A15: DAY 2 - UPPER BODY (Wednesday)
A16: 1 | B16: Landmine Press (1-arm) | C16: 3 | D16: 8 / arm | E16: 90 sec | F16: Reach long at the top
A17: 2 | B17: Chest-Supported DB Row | C17: 4 | D17: 10 | E17: 90 sec | F17: Pull elbow to back pocket
A18: 3 | B18: Push-Up (weighted if easy) | C18: 3 | D18: 12 | E18: 60 sec | F18: Full range, plank body
A19: 4 | B19: Half-Kneeling Cable Pulldown | C19: 3 | D19: 10 / arm | E19: 60 sec | F19: Ribs down, no lean
A20: 5 | B20: Prone Y-T-W Raises | C20: 2 | D20: 8 each | E20: 45 sec | F20: Light weight, squeeze scaps
A21: 6 | B21: Pallof Press | C21: 3 | D21: 10 / side | E21: 45 sec | F21: Resist rotation, brace
A24: DAY 3 - TOTAL BODY / POWER (Friday)
A25: 1 | B25: Box Jump | C25: 4 | D25: 3 | E25: 90 sec | F25: Land soft and quiet, step down
A26: 2 | B26: Goblet Squat | C26: 3 | D26: 10 | E26: 90 sec | F26: Elbows inside knees, chest tall
A27: 3 | B27: DB Bench Press | C27: 3 | D27: 8 | E27: 90 sec | F27: Controlled down, drive up
A28: 4 | B28: Inverted Row | C28: 3 | D28: 10 | E28: 60 sec | F28: Chest to bar, straight body
A29: 5 | B29: Farmer Carry | C29: 3 | D29: 40 yds | E29: 60 sec | F29: Tall posture, tight grip
A30: 6 | B30: Dead Bug | C30: 3 | D30: 8 / side | E30: 45 sec | F30: Low back pressed to floor
